<?xml version="1.0" ?>

<robot xmlns:xacro="https://www.ros.org/wiki/xacro" >
    <xacro:property name="PI" value="3.1415926535897931"/>
    <xacro:property name="frame_m" value="20"/>
    <xacro:property name="vslider_m" value="2"/>
    <xacro:property name="hslider_m" value="0.8"/>
    <xacro:property name="plug_m" value="0.2"/>
    <xacro:property name="hook_m" value="0.5"/>
    <xacro:property name="tip_m" value="0.2"/>

    <xacro:macro name="frame_macro" params="parent *origin">
      <joint name="joint_jazzy_frame" type="fixed">
        <xacro:insert_block name="origin"/>
        <parent link="${parent}"/>
        <child link="link_frame"/>
      </joint>
      <link name="link_frame">
        <visual>
          <origin rpy="0 0 0" xyz="0 0 0"/>
          <geometry>
            <mesh filename="package://ids_description/meshes/jazzy/frame.obj" scale="0.01 0.01 0.01"/>
          </geometry>
        </visual>
        <collision>
          <origin rpy=" 0 0 0" xyz="0 0 0"/>
          <geometry>
            <mesh filename="package://ids_description/meshes/jazzy/frame.obj" scale="0.01 0.01 0.01"/>
          </geometry>
        </collision>
        <inertial>
          <mass value="${frame_m}"/>
          <origin rpy="0 0 0" xyz="0 0 0"/>
          <inertia ixx="${frame_m*2.523e-3}" ixy="0" ixz="-${frame_m*5.1e-5}" iyy="${frame_m*2.346e-3}" iyz="0" izz="${frame_m*1.93e-4}"/>
        </inertial>
      </link>
      <!--vertivcal slider-->
      <joint name="joint_frame_vslider" type="prismatic">
        <origin xyz="0.1 0 0.02" rpy="0 0 0"/>
        <parent link="link_frame"/>
        <child link="link_vslider"/>
        <axis xyz="0 0 1"/>
        <limit upper="0.96" lower="0" effort="100.0" velocity="0.1"/>
        <dynamics damping="0" friction="5.0"/>
      </joint>
      <link name="link_vslider">
        <visual>
          <origin rpy="0 0 0" xyz="0 0 0"/>
          <geometry>
            <box size="0.04 0.36 0.04"/>
          </geometry>
        </visual>
        <collision>
          <origin rpy=" 0 0 0" xyz="0 0 0"/>
          <geometry>
            <box size="0.04 0.36 0.04"/>
          </geometry>
        </collision>
        <inertial>
          <mass value="${vslider_m}"/>
          <origin rpy="0 0 0" xyz="0 0 0"/>
          <inertia ixx="${(1/12)*vslider_m*(0.36*0.36+0.04*0.04)}" ixy="0" ixz="0" iyy="${(1/12)*vslider_m*(0.04*0.04+0.04*0.04)}" iyz="0" izz="${(1/12)*vslider_m*(0.04*0.04+0.36*0.36)}"/>
        </inertial>
      </link>
      <!--horizontal slider-->
      <joint name="joint_vslider_hslider" type="prismatic">
        <origin xyz="0 0 0" rpy="0 0 0"/>
        <parent link="link_vslider"/>
        <child link="link_hslider"/>
        <axis xyz="0 1 0"/>
        <limit upper="0.13" lower="-0.13" effort="100.0" velocity="0.1"/>
        <dynamics damping="0" friction="5.0"/>
      </joint>
      <link name="link_hslider">
        <visual>
          <origin rpy="1.57 0 0" xyz="0.02 0 0"/>
          <geometry>
            <mesh filename="package://ids_description/meshes/jazzy/hslider.obj" scale="0.01 0.01 0.01"/>
          </geometry>
        </visual>
        <collision>
          <origin rpy="1.57 0 0" xyz="0.02 0 0"/>
          <geometry>
            <mesh filename="package://ids_description/meshes/jazzy/hslider.obj" scale="0.01 0.01 0.01"/>
          </geometry>
        </collision>
        <inertial>
          <mass value="${hslider_m}"/>
          <origin rpy="1.57 0 0" xyz="0.095 0 0"/>
          <inertia ixx="${(1/12)*hslider_m*(0.04*0.04+0.04*0.04)}" ixy="0" ixz="0" iyy="${(1/12)*hslider_m*(0.15*0.15+0.04*0.04)}" iyz="0" izz="${(1/12)*hslider_m*(0.04*0.04+0.15*0.15)}"/>
        </inertial>
      </link>
      <!--plug-->
      <joint name="joint_hslider_plug" type="prismatic">
        <origin xyz="0 0 0" rpy="0 0 0"/>
        <parent link="link_hslider"/>
        <child link="link_plug"/>
        <axis xyz="1 0 0"/>
        <limit upper="0.1" lower="0" effort="100.0" velocity="0.1"/>
        <dynamics damping="0" friction="5.0"/>
      </joint>
      <link name="link_plug">
        <visual>
          <origin rpy="1.57 0 1.57" xyz="0.07 -0.011 0.011"/>
          <geometry>
            <mesh filename="package://ids_description/meshes/jazzy/plug.obj" scale="0.01 0.01 0.01"/>
          </geometry>
        </visual>
        <collision>
          <origin rpy="1.57 0 1.57" xyz="0.07 -0.011 0.011"/>
          <geometry>
            <mesh filename="package://ids_description/meshes/jazzy/plug.obj" scale="0.01 0.01 0.01"/>
          </geometry>
          <surface>
            <friction>
              <ode>
                <mu>0.01</mu>
                <mu2>0.01</mu2>
              </ode>
            </friction>
          </surface>
        </collision>
        <inertial>
          <mass value="${plug_m}"/>
          <origin rpy="0 0 0" xyz="0.015 0 0"/>
          <inertia ixx="${(1/12)*plug_m*(0.022*0.022+0.022*0.022)}" ixy="0" ixz="0" iyy="${(1/12)*plug_m*(0.022*0.022+0.07*0.07)}" iyz="0" izz="${(1/12)*plug_m*(0.07*0.07+0.022*0.022)}"/>
        </inertial>
      </link>

      <!--contact bumper-->
      <joint name="joint_contact_bp" type="revolute">
        <origin xyz="0.161 0 -0.00636" rpy="0 0 0"/>
        <parent link="link_plug"/>
        <child link="link_contact_bp"/>
        <axis xyz="1 0 0"/>
        <limit upper="0" lower="0" effort="0.0" velocity="0.0"/>
      </joint>
      <link name="link_contact_bp">
        <visual>
          <origin rpy="0 0 0" xyz="0 0 0"/>
          <geometry>
            <box size="0.001 0.001 0.001"/>
          </geometry>
        </visual>
        <collision name="bump_sensor_collision">
          <origin rpy="0 0 0" xyz="0 0 0"/>
          <geometry>
            <box size="0.001 0.001 0.001"/>
          </geometry>
        </collision>
        <inertial>
          <mass value="0.001"/>
          <origin rpy="0 0 0" xyz="0 0 0"/>
          <inertia ixx="0.000000001" ixy="0" ixz="0" iyy="0.000000001" iyz="0" izz="0.000000001"/>
        </inertial>
      </link>

      <!--hook for door opening-->
      <joint name="joint_frame_hook" type="revolute">
        <origin xyz="0.31 -0.23 0.3" rpy="0 0 0"/>
        <parent link="link_frame"/>
        <child link="link_hook"/>
        <axis xyz="0 -1 0"/>
        <limit upper="1.57" lower="0" effort="300.0" velocity="0.1"/>
      </joint>
      <link name="link_hook">
        <visual>
          <origin rpy="0 0 0" xyz="0 0 0"/>
          <geometry>
            <box size="0.4 0.02 0.01"/>
          </geometry>
        </visual>
        <collision>
          <origin rpy="0 0 0" xyz="0 0 0"/>
          <geometry>
            <box size="0.4 0.02 0.01"/>
          </geometry>
          <surface>
            <friction>
              <ode>
                <mu>0.01</mu>
                <mu2>0.01</mu2>
              </ode>
            </friction>
          </surface>
        </collision>
        <inertial>
          <mass value="${hook_m}"/>
          <origin rpy="0 0 0" xyz="0.1 0 0"/>
          <inertia ixx="${(1/3)*hook_m*(0.01*0.01+0.02*0.02)}" ixy="0" ixz="0" iyy="${(1/3)*hook_m*(4*0.4*0.4+0.01*0.01)}" iyz="0" izz="${(1/3)*hook_m*(4*0.4*0.4+0.02*0.02)}"/>
        </inertial>
      </link>

      <joint name="joint_hook_tip" type="fixed">
        <origin xyz="0.2 0 0" rpy="0 0 0"/>
        <parent link="link_hook"/>
        <child link="link_tip"/>
      </joint>
      <link name="link_tip">
        <visual>
          <origin rpy="0 0 0" xyz="0.01 0.01 0"/>
          <geometry>
            <box size="0.02 0.04 0.01"/>
          </geometry>
        </visual>
        <collision>
          <origin rpy="0 0 0" xyz="0.01 0.01 0"/>
          <geometry>
            <box size="0.02 0.04 0.01"/>
          </geometry>
        </collision>
        <inertial>
          <mass value="${tip_m}"/>
          <origin rpy="0 0 0" xyz="0.01 0.02 0"/>
          <inertia ixx="${(1/12)*tip_m*(0.04*0.04+0.01*0.01)}" ixy="0" ixz="0" iyy="${(1/3)*tip_m*(0.02*0.02+0.01*0.01)}" iyz="0" izz="${(1/12)*tip_m*(0.02*0.02+0.04*0.04)}"/>
        </inertial>
      </link>

      <!--transmission controls-->
      <transmission name="vtrans">
        <type>transmission_interface/SimpleTransmission</type>
        <joint name="joint_frame_vslider">
          <hardwareInterface>hardware_interface/EffortJointInterface</hardwareInterface>
        </joint>
        <actuator name="vmotor">
          <hardwareInterface>hardware_interface/EffortJointInterface</hardwareInterface>
          <mechanicalReduction>1</mechanicalReduction>
        </actuator>
      </transmission>
      <transmission name="htrans">
        <type>transmission_interface/SimpleTransmission</type>
        <joint name="joint_vslider_hslider">
          <hardwareInterface>hardware_interface/EffortJointInterface</hardwareInterface>
        </joint>
        <actuator name="hmotor">
          <hardwareInterface>hardware_interface/EffortJointInterface</hardwareInterface>
          <mechanicalReduction>1</mechanicalReduction>
        </actuator>
      </transmission>
      <transmission name="ftrans">
        <type>transmission_interface/SimpleTransmission</type>
        <joint name="joint_hslider_plug">
          <hardwareInterface>hardware_interface/EffortJointInterface</hardwareInterface>
        </joint>
        <actuator name="fmotor">
          <hardwareInterface>hardware_interface/EffortJointInterface</hardwareInterface>
          <mechanicalReduction>1</mechanicalReduction>
        </actuator>
      </transmission>
      <transmission name="strans">
        <type>transmission_interface/SimpleTransmission</type>
        <joint name="joint_frame_hook">
          <hardwareInterface>hardware_interface/EffortJointInterface</hardwareInterface>
        </joint>
        <actuator name="smotor">
          <hardwareInterface>hardware_interface/EffortJointInterface</hardwareInterface>
          <mechanicalReduction>1</mechanicalReduction>
        </actuator>
      </transmission>

      <gazebo>
        <plugin name="gazebo_ros_control" filename="libgazebo_ros_control.so">
          <robotSimType>gazebo_ros_control/DefaultRobotHWSim</robotSimType>
          <legacyModeNS>true</legacyModeNS>
          <robotNamespace>$(arg ns)</robotNamespace>
        </plugin>
      </gazebo>

      <!--materials-->
      <gazebo reference="link_frame">
        <material>Gazebo/Orange</material>
      </gazebo>
      <gazebo reference="link_vslider">
        <material>Gazebo/White</material>
      </gazebo>
      <gazebo reference="link_hslider">
        <material>Gazebo/Orange</material>
      </gazebo>
      <gazebo reference="link_plug">
        <material>Gazebo/White</material>
      </gazebo>
      <gazebo reference="link_battery">
        <material>Gazebo/Black</material>
      </gazebo>
      <gazebo reference="link_hook">
        <material>Gazebo/Black</material>
      </gazebo>
      <gazebo reference="link_tip">
        <material>Gazebo/Black</material>
      </gazebo>
      <gazebo reference="link_contact_bp">
        <material>Gazebo/Blue</material>
      </gazebo>

      <!--sensors-->
      <gazebo reference="joint_frame_hook">
        <provideFeedback>true</provideFeedback>
      </gazebo>
      <gazebo reference="joint_vslider_hslider">
        <provideFeedback>true</provideFeedback>
      </gazebo>

      <gazebo>
        <plugin name="sidebar_force_sensor" filename="libgazebo_ros_ft_sensor.so">
          <updateRate>100.0</updateRate>
          <topicName>$(arg ns)/ft_sidebar</topicName>
          <jointName>joint_frame_hook</jointName>
          <noise>
            <type>guassian</type>
            <mean>0.0</mean>
            <stddev>0.003</stddev>
          </noise>
        </plugin>
      </gazebo>

      <gazebo>
        <plugin name="endeffector_force_sensor" filename="libgazebo_ros_ft_sensor.so">
          <updateRate>100.0</updateRate>
          <topicName>$(arg ns)/ft_endeffector</topicName>
          <jointName>joint_vslider_hslider</jointName>
          <noise>
            <type>guassian</type>
            <mean>0.0</mean>
            <stddev>0.003</stddev>
          </noise>
        </plugin>
      </gazebo>
      <gazebo reference="link_contact_bp">
        <sensor name="main_bumper" type="contact">
          <contact>
            <collision>link_contact_bp_fixed_joint_lump__bump_sensor_collision_collision</collision>
          </contact>
          <plugin name="gazebo_ros_bumper_controller" filename="libgazebo_ros_bumper.so">
            <bumperTopicName>$(arg ns)/bumper_plug</bumperTopicName>
            <frameName>$(arg tf_prefix)/link_bp</frameName>
            <alwaysOn>true</alwaysOn>
            <updateRate>100.0</updateRate>
          </plugin>
        </sensor>
      </gazebo>

    </xacro:macro>
</robot>
